<?xml version="1.0"?>
<robot xmlns:xacro="http://www.ros.org/wiki/xacro" name="rover">

<xacro:arg name="params_path" default=""/>
<xacro:property name="params_path" value="$(arg params_path)"/>

<xacro:property name="param" value="${xacro.load_yaml(params_path)}"/>
<!-- <link name="base_link">
    <visual>
        <geometry>
            <box size="${bx} ${by} ${bh}"/>
        </geometry>
        <material name="white"/>
    </visual>
    <collision>
            <origin xyz="0 0 0.05" rpy="0 0 0"/>
            <geometry>
                <box size="0.01 0.01 0.01" />
            </geometry>
        </collision>
        <inertial>
            <origin xyz="0 0 0.05" rpy="0 0 0"/>
            <mass value="0.001" />
            <inertia ixx="2.26" ixy="0.0" ixz="0.0" iyy="6.26" iyz="0.0" izz="8.5" />
        </inertial>
</link> -->
<link name='base_link'>
            <origin xyz="0 0 0.1" rpy="0 0 0"/>

            <collision name='collision'>
            <origin xyz="0 0 0.1" rpy="0 0 0"/>
              <geometry>
                <box size="0.4 0.2 0.1"/>
              </geometry>
            </collision>

            <visual name='visual'>
              <geometry>
                 <box size="0.4 0.2 0.1"/>
              </geometry>
            </visual>
                      <collision name='caster_collision'>
            <origin xyz="-0.15 0 0" rpy="-0.05 0 0"/>
            <geometry>
                <sphere radius="0.5"/>
          
            </geometry>

            <!-- <surface>
              <friction>
                <ode>
                  <mu>0</mu>
                  <mu2>0</mu2>
                  <slip1>1.0</slip1>
                  <slip2>1.0</slip2>
                </ode>
              </friction>
            </surface> -->
          </collision>

          <visual name='caster_visual'>
            <origin xyz="-0.15 0 0" rpy="-0.05 0 0"/>
            <geometry>
              <sphere radius="0.5"/>
            </geometry>
          </visual>
          </link>
      <link name="left_wheel">
        <origin xyz="0.1 0.13 0.1" rpy="0 1.5707 1.5707"/>
        <collision name="collision">
        <origin xyz="-0.15 0 0" rpy="-0.05 0 0"/>
          <geometry>
            <cylinder length="0.05" radius="0.1"/>
          </geometry>
        </collision>
        <visual name="visual">
          <geometry>
            <cylinder length="0.05" radius="0.1"/>
          </geometry>
        </visual>
      </link>
      <link name="right_wheel">
        <collision name="collision">
        <origin xyz="0.1 -0.13 0.1" rpy="0 1.5707 1.5707"/>
          <geometry>
           <cylinder length="0.05" radius="0.1"/>
          </geometry>
        </collision>
        <visual name="visual">
          <geometry>
            <cylinder length="0.05" radius="0.1"/>
          </geometry>
        </visual>
      </link>
      <joint name="left_wheel_hinge" type="continuous" >
        <parent link="base_link"/>
        <child link="left_wheel"/>
        <origin xyz="0 0 -0.03" rpy="0 0 0"/>
        <axis xyz="0 1 0"/>
      </joint>

      <joint name="right_wheel_hinge" type="continuous" >
        <parent link="base_link"/>
        <child link="right_wheel"/>
        <origin xyz="0 0 0.03" rpy="0 0 0"/>
        <axis xyz="0 1 0"/>
      </joint>

<xacro:include filename="rover_gazebo.xacro" />

</robot>